Workbook

Sheet Leia-me
A1: Base de dados da clínica — estrutura e orientações
A2: Planilha-base para alimentar o SaaS e o painel da reunião semanal.
A4: Legenda
A5: Célula amarela | B5: Preencher (dado coletado)
A6: Célula branca | B6: Calculada automaticamente — não editar
A8: Fluxo de uso
A9: 1. Config: confirme os nomes dos fisioterapeutas (Fisio 1 / Fisio 2), as metas semanais e mensais e as listas de opções.
A10: 2. Base_Semanal: ao fim de cada semana, preencha a linha da semana (leads, avaliações, contratos, atendimentos, agenda, tempos).
A11: 3. Contratos: registre cada avaliação ou protocolo contratado com valor, condição e forma de pagamento e canal de ingresso.
A12: 4. Financeiro: registre receitas, gastos, impostos e marketing; use o status para pendências (Pendente) e inadimplência (Atrasado).
A13: 5. Leads_Canal: distribua os leads da semana por canal (meios de comunicação de ingresso).
A14: 6. Reuniao_Semanal e Plano_Acao: registre o qualitativo da reunião e as ações 5W2H.
A15: 7. Painel_Semanal: escolha a semana na célula C3 e conduza a reunião pelo painel. Resumo_Semanal e Resumo_Mensal consolidam tudo.
A17: Premissas
A18: Semanas seguem o padrão ISO (segunda a domingo), identificadas como AAAA-Sww; o mês de uma semana é o mês da sua data de início.
A19: Contratos e lançamentos financeiros recebem semana e mês automaticamente pela data informada.
A20: As linhas marcadas como 'Exemplo' (semanas 2026-S39, S40 e S41) são ilustrativas e devem ser substituídas pelos dados reais.
... A26: Dicionário de dados (para modelagem do SaaS)
A27: Aba (tabela) | B27: Campo | C27: Origem | D27: Descrição
A28: Base_Semanal | B28: id_semana | C28: preenchido | D28: Identificador da semana (AAAA-Sww), pré-preenchido a partir do Calendário
A29: Base_Semanal | B29: Início | C29: automático | D29: Data de início da semana (automático)
A30: Base_Semanal | B30: Fim | C30: automático | D30: Data de fim da semana (automático)
A31: Base_Semanal | B31: Mês | C31: automático | D31: Mês de referência AAAA-MM (automático)
A32: Base_Semanal | B32: Leads recebidos | C32: preenchido | D32: Total de leads recebidos na semana
A33: Base_Semanal | B33: Aval. agendadas | C33: preenchido | D33: Avaliações agendadas na semana
A34: Base_Semanal | B34: Aval. canceladas | C34: preenchido | D34: Avaliações canceladas na semana
A35: Base_Semanal | B35: Aval. realizadas Fisio 1 | C35: preenchido | D35: Avaliações realizadas pelo Fisio 1
A36: Base_Semanal | B36: Aval. realizadas Fisio 2 | C36: preenchido | D36: Avaliações realizadas pelo Fisio 2
A37: Base_Semanal | B37: Contratos fechados Fisio 1 | C37: preenchido | D37: Contratos (tratamentos) fechados pelo Fisio 1
A38: Base_Semanal | B38: Contratos fechados Fisio 2 | C38: preenchido | D38: Contratos (tratamentos) fechados pelo Fisio 2
... A185: Resumo_Mensal | B185: CAC (marketing / novos pac.) | C185: automático | D185: Calculado por mês

Sheet Painel_Semanal
A1: Painel de resultados — reunião semanal
A2: Escolha a semana na célula amarela (C3). Tudo o mais é calculado.
B3: Semana selecionada | C3: 2026-S40 | D3: Semana anterior | E3: =IFERROR(INDEX(Calendario!$A$4:$A$107,MATCH($C$3,Calendario!$A$4:$A$107,0)-1),"") -> 2026-S39 | F3: Próxima semana | G3: =IFERROR(INDEX(Calendario!$A$4:$A$107,MATCH($C$3,Calendario!$A$4:$A$107,0)+1),"") -> 2026-S41
B4: Período | C4: =IFERROR(INDEX(Calendario!$B$4:$B$107,MATCH($C$3,Calendario!$A$4:$A$107,0)),"") -> 46293 | D4: =IFERROR(INDEX(Calendario!$C$4:$C$107,MATCH($C$3,Calendario!$A$4:$A$107,0)),"") -> 46299
B5: Mês | C5: =IFERROR(INDEX(Calendario!$D$4:$D$107,MATCH($C$3,Calendario!$A$4:$A$107,0)),"") -> 2026-09
B7: 1. ABERTURA
B8: Resultado geral (automático — leads, avaliações, contratos, atendimentos, receita e gastos vs. semana anterior) | C8: =IF($C$3="","",IF((SIGN(N(IFERROR(INDEX(Resumo_Semanal!$E$4:$E$107,MATCH($C$3,Resumo_Semanal!$A$4:$A$107,0)),""))-N(IFERROR(INDEX(Resumo_Semanal!$E$4:$E$107,MATCH($E$3,Resumo_Semanal!$A$4:$A$107,0)),"")))+SIGN(N(IFERROR(INDEX(Resumo_Semanal!$J$4:$J$107,MATCH($C$3,Resumo_Semanal!$A$4:$A$107,0)),""))-N(IFERROR(INDEX(Resumo_Semanal!$J$4:$J$107,MATCH($E$3,Resumo_Semanal!$A$4:$A$107,0)),"")))+SIGN(N(IFERROR(INDEX(Resumo_Semanal!$N$4:$N$107,MATCH($C$3,Resumo_Semanal!$A$4:$A$107,0)),""))-N(IFERROR(INDEX(Resumo_Semanal!$N$4:$N$107,MATCH($E$3,Resumo_Semanal!$A$4:$A$107,0)),"")))+SIGN(N(IFERROR(INDEX(Resumo_Semanal!$R$4:$R$107,MATCH($C$3,Resumo_Semanal!$A$4:$A$107,0)),""))-N(IFERROR(INDEX(Resumo_Semanal!$R$4:$R$107,MATCH($E$3,Resumo_Semanal!$A$4:$A$107,0)),"")))+SIGN(N(IFERROR(INDEX(Resumo_Semanal!$AI$4:$AI$107,MATCH($C$3,Resumo_Semanal!$A$4:$A$107,0)),""))-N(IFERROR(INDEX(Resumo_Semanal!$AI$4:$AI$107,MATCH($E$3,Resumo_Semanal!$A$4:$A$107,0)),"")))-SIGN(N(IFERROR(INDEX(Resumo_Semanal!$AJ$4:$AJ$107,MATCH($C$3,Resumo_Semanal!$A$4:$A$107,0)),""))-N(IFERROR(INDEX(Resumo_Semanal!$AJ$4:$AJ$107,MATCH($E$3,Resumo_Semanal!$A$4:$A$107,0)),""))))>0,"Melhor",IF((SIGN(N(IFERROR(INDEX(Resumo_Semanal!$E$4:$E$107,MATCH($C$3,Resumo_Semanal!$A$4:$A$107,0)),""))-N(IFERROR(INDEX(Resumo_Semanal!$E$4:$E$107,MATCH($E$3,Resumo_Semanal!$A$4:$A$107,0)),"")))+SIGN(N(IFERROR(INDEX(Resumo_Semanal!$J$4:$J$107,MATCH($C$3,Resumo_Semanal!$A$4:$A$107,0)),""))-N(IFERROR(INDEX(Resumo_Semanal!$J$4:$J$107,MATCH($E$3,Resumo_Semanal!$A$4:$A$107,0)),"")))+SIGN(N(IFERROR(INDEX(Resumo_Semanal!$N$4:$N$107,MATCH($C$3,Resumo_Semanal!$A$4:$A$107,0)),""))-N(IFERROR(INDEX(Resumo_Semanal!$N$4:$N$107,MATCH($E$3,Resumo_Semanal!$A$4:$A$107,0)),"")))+SIGN(N(IFERROR(INDEX(Resumo_Semanal!$R$4:$R$107,MATCH($C$3,Resumo_Semanal!$A$4:$A$107,0)),""))-N(IFERROR(INDEX(Resumo_Semanal!$R$4:$R$107,MATCH($E$3,Resumo_Semanal!$A$4:$A$107,0)),"")))+SIGN(N(IFERROR(INDEX(Resumo_Semanal!$AI$4:$AI$107,MATCH($C$3,Resumo_Semanal!$A$4:$A$107,0)),""))-N(IFERROR(INDEX(Resumo_Semanal!$AI$4:$AI$107,MATCH($E$3,Resumo_Semanal!$A$4:$A$107,0)),"")))-SIGN(N(IFERROR(INDEX(Resumo_Semanal!$AJ$4:$AJ$107,MATCH($C$3,Resumo_Semanal!$A$4:$A$107,0)),""))-N(IFERROR(INDEX(Resumo_Semanal!$AJ$4:$AJ$107,MATCH($E$3,Resumo_Semanal!$A$4:$A$107,0)),""))))<0,"Pior","Igual"))) -> Melhor
B9: Resultado geral (registrado na reunião) | C9: =IFERROR(INDEX(Reuniao_Semanal!$B$4:$B$203,MATCH($C$3,Reuniao_Semanal!$A$4:$A$203,0)),"") -> Melhor
B10: Pontos positivos | C10: =IFERROR(INDEX(Reuniao_Semanal!$C$4:$C$203,MATCH($C$3,Reuniao_Semanal!$A$4:$A$203,0)),"") -> Receita acima da meta; 4 protocolos fechados por indicação
B11: Pontos a melhorar | C11: =IFERROR(INDEX(Reuniao_Semanal!$D$4:$D$203,MATCH($C$3,Reuniao_Semanal!$A$4:$A$203,0)),"") -> Taxa de ocupação da tarde abaixo de 90%; 5 cancelamentos de atendimento
B13: 2. INDICADORES-CHAVE — CRESCIMENTO
B14: Indicador | C14: Semana atual | D14: Semana anterior | E14: Variação | F14: Meta semanal | G14: % da meta | H14: Acumulado no mês | I14: Meta mensal
B15: Leads recebidos | C15: =IFERROR(INDEX(Resumo_Semanal!$E$4:$E$107,MATCH($C$3,Resumo_Semanal!$A$4:$A$107,0)),"") -> 45 | D15: =IFERROR(INDEX(Resumo_Semanal!$E$4:$E$107,MATCH($E$3,Resumo_Semanal!$A$4:$A$107,0)),"") -> 38 | E15: =IF(OR(C15="",D15=""),"",C15-D15) -> 7 | F15: =Config!$B$10 -> 40 | G15: =IF(OR(C15="",F15=0),"",C15/F15) -> 1.125 | H15: =SUMIFS(Resumo_Semanal!$E$4:$E$107,Resumo_Semanal!$D$4:$D$107,$C$5,Resumo_Semanal!$B$4:$B$107,"<="&$C$4) -> 83 | I15: =Config!$C$10 -> 170
B16: Novos pacientes | C16: =IFERROR(INDEX(Resumo_Semanal!$T$4:$T$107,MATCH($C$3,Resumo_Semanal!$A$4:$A$107,0)),"") -> 9 | D16: =IFERROR(INDEX(Resumo_Semanal!$T$4:$T$107,MATCH($E$3,Resumo_Semanal!$A$4:$A$107,0)),"") -> 6 | E16: =IF(OR(C16="",D16=""),"",C16-D16) -> 3 | F16: =Config!$B$11 -> 8 | G16: =IF(OR(C16="",F16=0),"",C16/F16) -> 1.125 | H16: =SUMIFS(Resumo_Semanal!$T$4:$T$107,Resumo_Semanal!$D$4:$D$107,$C$5,Resumo_Semanal!$B$4:$B$107,"<="&$C$4) -> 15 | I16: =Config!$C$11 -> 32
B17: Avaliações agendadas | C17: =IFERROR(INDEX(Resumo_Semanal!$F$4:$F$107,MATCH($C$3,Resumo_Semanal!$A$4:$A$107,0)),"") -> 16 | D17: =IFERROR(INDEX(Resumo_Semanal!$F$4:$F$107,MATCH($E$3,Resumo_Semanal!$A$4:$A$107,0)),"") -> 14 | E17: =IF(OR(C17="",D17=""),"",C17-D17) -> 2 | H17: =SUMIFS(Resumo_Semanal!$F$4:$F$107,Resumo_Semanal!$D$4:$D$107,$C$5,Resumo_Semanal!$B$4:$B$107,"<="&$C$4) -> 30
B18: Avaliações canceladas | C18: =IFERROR(INDEX(Resumo_Semanal!$G$4:$G$107,MATCH($C$3,Resumo_Semanal!$A$4:$A$107,0)),"") -> 1 | D18: =IFERROR(INDEX(Resumo_Semanal!$G$4:$G$107,MATCH($E$3,Resumo_Semanal!$A$4:$A$107,0)),"") -> 2 | E18: =IF(OR(C18="",D18=""),"",C18-D18) -> -1 | H18: =SUMIFS(Resumo_Semanal!$G$4:$G$107,Resumo_Semanal!$D$4:$D$107,$C$5,Resumo_Semanal!$B$4:$B$107,"<="&$C$4) -> 3
B19: Taxa de cancelamento de avaliações | C19: =IFERROR(INDEX(Resumo_Semanal!$K$4:$K$107,MATCH($C$3,Resumo_Semanal!$A$4:$A$107,0)),"") -> 0.0625 | D19: =IFERROR(INDEX(Resumo_Semanal!$K$4:$K$107,MATCH($E$3,Resumo_Semanal!$A$4:$A$107,0)),"") -> 0.14285714 | E19: =IF(OR(C19="",D19=""),"",C19-D19) -> -0.080357143 | F19: =Config!$B$20 -> 0.15 | G19: =IF(OR(C19="",F19=0),"",C19/F19) -> 0.41666667 | I19: =Config!$C$20 -> 0.15
B20: Avaliações realizadas — total | C20: =IFERROR(INDEX(Resumo_Semanal!$J$4:$J$107,MATCH($C$3,Resumo_Semanal!$A$4:$A$107,0)),"") -> 14 | D20: =IFERROR(INDEX(Resumo_Semanal!$J$4:$J$107,MATCH($E$3,Resumo_Semanal!$A$4:$A$107,0)),"") -> 11 | E20: =IF(OR(C20="",D20=""),"",C20-D20) -> 3 | F20: =Config!$B$12 -> 12 | G20: =IF(OR(C20="",F20=0),"",C20/F20) -> 1.1666667 | H20: =SUMIFS(Resumo_Semanal!$J$4:$J$107,Resumo_Semanal!$D$4:$D$107,$C$5,Resumo_Semanal!$B$4:$B$107,"<="&$C$4) -> 25 | I20: =Config!$C$12 -> 50
B21: ="Avaliações realizadas — "&Config!$B$5 -> Avaliações realizadas — Ariosto | C21: =IFERROR(INDEX(Resumo_Semanal!$H$4:$H$107,MATCH($C$3,Resumo_Semanal!$A$4:$A$107,0)),"") -> 8 | D21: =IFERROR(INDEX(Resumo_Semanal!$H$4:$H$107,MATCH($E$3,Resumo_Semanal!$A$4:$A$107,0)),"") -> 6 | E21: =IF(OR(C21="",D21=""),"",C21-D21) -> 2 | H21: =SUMIFS(Resumo_Semanal!$H$4:$H$107,Resumo_Semanal!$D$4:$D$107,$C$5,Resumo_Semanal!$B$4:$B$107,"<="&$C$4) -> 14
B22: ="Avaliações realizadas — "&Config!$B$6 -> Avaliações realizadas — Tássia | C22: =IFERROR(INDEX(Resumo_Semanal!$I$4:$I$107,MATCH($C$3,Resumo_Semanal!$A$4:$A$107,0)),"") -> 6 | D22: =IFERROR(INDEX(Resumo_Semanal!$I$4:$I$107,MATCH($E$3,Resumo_Semanal!$A$4:$A$107,0)),"") -> 5 | E22: =IF(OR(C22="",D22=""),"",C22-D22) -> 1 | H22: =SUMIFS(Resumo_Semanal!$I$4:$I$107,Resumo_Semanal!$D$4:$D$107,$C$5,Resumo_Semanal!$B$4:$B$107,"<="&$C$4) -> 11
B23: Tratamentos contratados — total | C23: =IFERROR(INDEX(Resumo_Semanal!$N$4:$N$107,MATCH($C$3,Resumo_Semanal!$A$4:$A$107,0)),"") -> 10 | D23: =IFERROR(INDEX(Resumo_Semanal!$N$4:$N$107,MATCH($E$3,Resumo_Semanal!$A$4:$A$107,0)),"") -> 7 | E23: =IF(OR(C23="",D23=""),"",C23-D23) -> 3 | F23: =Config!$B$13 -> 8 | G23: =IF(OR(C23="",F23=0),"",C23/F23) -> 1.25 | H23: =SUMIFS(Resumo_Semanal!$N$4:$N$107,Resumo_Semanal!$D$4:$D$107,$C$5,Resumo_Semanal!$B$4:$B$107,"<="&$C$4) -> 17 | I23: =Config!$C$13 -> 32
B24: ="Tratamentos contratados — "&Config!$B$5 -> Tratamentos contratados — Ariosto | C24: =IFERROR(INDEX(Resumo_Semanal!$L$4:$L$107,MATCH($C$3,Resumo_Semanal!$A$4:$A$107,0)),"") -> 6 | D24: =IFERROR(INDEX(Resumo_Semanal!$L$4:$L$107,MATCH($E$3,Resumo_Semanal!$A$4:$A$107,0)),"") -> 4 | E24: =IF(OR(C24="",D24=""),"",C24-D24) -> 2 | H24: =SUMIFS(Resumo_Semanal!$L$4:$L$107,Resumo_Semanal!$D$4:$D$107,$C$5,Resumo_Semanal!$B$4:$B$107,"<="&$C$4) -> 10
B25: ="Tratamentos contratados — "&Config!$B$6 -> Tratamentos contratados — Tássia | C25: =IFERROR(INDEX(Resumo_Semanal!$M$4:$M$107,MATCH($C$3,Resumo_Semanal!$A$4:$A$107,0)),"") -> 4 | D25: =IFERROR(INDEX(Resumo_Semanal!$M$4:$M$107,MATCH($E$3,Resumo_Semanal!$A$4:$A$107,0)),"") -> 3 | E25: =IF(OR(C25="",D25=""),"",C25-D25) -> 1 | H25: =SUMIFS(Resumo_Semanal!$M$4:$M$107,Resumo_Semanal!$D$4:$D$107,$C$5,Resumo_Semanal!$B$4:$B$107,"<="&$C$4) -> 7
B26: Conversão avaliação → contrato | C26: =IFERROR(INDEX(Resumo_Semanal!$O$4:$O$107,MATCH($C$3,Resumo_Semanal!$A$4:$A$107,0)),"") -> 0.71428571 | D26: =IFERROR(INDEX(Resumo_Semanal!$O$4:$O$107,MATCH($E$3,Resumo_Semanal!$A$4:$A$107,0)),"") -> 0.63636364 | E26: =IF(OR(C26="",D26=""),"",C26-D26) -> 0.077922078 | F26: =Config!$B$19 -> 0.6 | G26: =IF(OR(C26="",F26=0),"",C26/F26) -> 1.1904762 | I26: =Config!$C$19 -> 0.6
B27: Avaliações contratadas (qtd) | C27: =IFERROR(INDEX(Resumo_Semanal!$AB$4:$AB$107,MATCH($C$3,Resumo_Semanal!$A$4:$A$107,0)),"") -> 2 | D27: =IFERROR(INDEX(Resumo_Semanal!$AB$4:$AB$107,MATCH($E$3,Resumo_Semanal!$A$4:$A$107,0)),"") -> 1 | E27: =IF(OR(C27="",D27=""),"",C27-D27) -> 1 | H27: =SUMIFS(Resumo_Semanal!$AB$4:$AB$107,Resumo_Semanal!$D$4:$D$107,$C$5,Resumo_Semanal!$B$4:$B$107,"<="&$C$4) -> 3
B28: Valor de avaliações contratadas | C28: =IFERROR(INDEX(Resumo_Semanal!$AC$4:$AC$107,MATCH($C$3,Resumo_Semanal!$A$4:$A$107,0)),"") -> 300 | D28: =IFERROR(INDEX(Resumo_Semanal!$AC$4:$AC$107,MATCH($E$3,Resumo_Semanal!$A$4:$A$107,0)),"") -> 150 | E28: =IF(OR(C28="",D28=""),"",C28-D28) -> 150 | H28: =SUMIFS(Resumo_Semanal!$AC$4:$AC$107,Resumo_Semanal!$D$4:$D$107,$C$5,Resumo_Semanal!$B$4:$B$107,"<="&$C$4) -> 450
B29: Protocolos contratados (qtd) | C29: =IFERROR(INDEX(Resumo_Semanal!$AD$4:$AD$107,MATCH($C$3,Resumo_Semanal!$A$4:$A$107,0)),"") -> 2 | D29: =IFERROR(INDEX(Resumo_Semanal!$AD$4:$AD$107,MATCH($E$3,Resumo_Semanal!$A$4:$A$107,0)),"") -> 2 | E29: =IF(OR(C29="",D29=""),"",C29-D29) -> 0 | H29: =SUMIFS(Resumo_Semanal!$AD$4:$AD$107,Resumo_Semanal!$D$4:$D$107,$C$5,Resumo_Semanal!$B$4:$B$107,"<="&$C$4) -> 4
B30: Valor de protocolos contratados | C30: =IFERROR(INDEX(Resumo_Semanal!$AE$4:$AE$107,MATCH($C$3,Resumo_Semanal!$A$4:$A$107,0)),"") -> 6800 | D30: =IFERROR(INDEX(Resumo_Semanal!$AE$4:$AE$107,MATCH($E$3,Resumo_Semanal!$A$4:$A$107,0)),"") -> 6200 | E30: =IF(OR(C30="",D30=""),"",C30-D30) -> 600 | H30: =SUMIFS(Resumo_Semanal!$AE$4:$AE$107,Resumo_Semanal!$D$4:$D$107,$C$5,Resumo_Semanal!$B$4:$B$107,"<="&$C$4) -> 13000
B31: Contratos à vista (qtd) | C31: =IFERROR(INDEX(Resumo_Semanal!$AG$4:$AG$107,MATCH($C$3,Resumo_Semanal!$A$4:$A$107,0)),"") -> 2 | D31: =IFERROR(INDEX(Resumo_Semanal!$AG$4:$AG$107,MATCH($E$3,Resumo_Semanal!$A$4:$A$107,0)),"") -> 2 | E31: =IF(OR(C31="",D31=""),"",C31-D31) -> 0 | H31: =SUMIFS(Resumo_Semanal!$AG$4:$AG$107,Resumo_Semanal!$D$4:$D$107,$C$5,Resumo_Semanal!$B$4:$B$107,"<="&$C$4) -> 4
B32: Contratos parcelados (qtd) | C32: =IFERROR(INDEX(Resumo_Semanal!$AH$4:$AH$107,MATCH($C$3,Resumo_Semanal!$A$4:$A$107,0)),"") -> 2 | D32: =IFERROR(INDEX(Resumo_Semanal!$AH$4:$AH$107,MATCH($E$3,Resumo_Semanal!$A$4:$A$107,0)),"") -> 1 | E32: =IF(OR(C32="",D32=""),"",C32-D32) -> 1 | H32: =SUMIFS(Resumo_Semanal!$AH$4:$AH$107,Resumo_Semanal!$D$4:$D$107,$C$5,Resumo_Semanal!$B$4:$B$107,"<="&$C$4) -> 3
B34: Meios de comunicação de ingresso (leads por canal)
B35: Canal | C35: Semana atual | D35: Semana anterior | E35: Variação | F35: % do total (atual)
B36: =Config!$I$10 -> Instagram | C36: =SUMIFS(Leads_Canal!$C$4:$C$503,Leads_Canal!$A$4:$A$503,$C$3,Leads_Canal!$B$4:$B$503,Config!$I$10) -> 20 | D36: =SUMIFS(Leads_Canal!$C$4:$C$503,Leads_Canal!$A$4:$A$503,$E$3,Leads_Canal!$B$4:$B$503,Config!$I$10) -> 16 | E36: =C36-D36 -> 4 | F36: =IF(SUM($C$36:$C$44)=0,"",C36/SUM($C$36:$C$44)) -> 0.44444444
B37: =Config!$I$11 -> Google | C37: =SUMIFS(Leads_Canal!$C$4:$C$503,Leads_Canal!$A$4:$A$503,$C$3,Leads_Canal!$B$4:$B$503,Config!$I$11) -> 12 | D37: =SUMIFS(Leads_Canal!$C$4:$C$503,Leads_Canal!$A$4:$A$503,$E$3,Leads_Canal!$B$4:$B$503,Config!$I$11) -> 10 | E37: =C37-D37 -> 2 | F37: =IF(SUM($C$36:$C$44)=0,"",C37/SUM($C$36:$C$44)) -> 0.26666667
B38: =Config!$I$12 -> WhatsApp direto | C38: =SUMIFS(Leads_Canal!$C$4:$C$503,Leads_Canal!$A$4:$A$503,$C$3,Leads_Canal!$B$4:$B$503,Config!$I$12) -> 5 | D38: =SUMIFS(Leads_Canal!$C$4:$C$503,Leads_Canal!$A$4:$A$503,$E$3,Leads_Canal!$B$4:$B$503,Config!$I$12) -> 5 | E38: =C38-D38 -> 0 | F38: =IF(SUM($C$36:$C$44)=0,"",C38/SUM($C$36:$C$44)) -> 0.11111111
B39: =Config!$I$13 -> Indicação | C39: =SUMIFS(Leads_Canal!$C$4:$C$503,Leads_Canal!$A$4:$A$503,$C$3,Leads_Canal!$B$4:$B$503,Config!$I$13) -> 8 | D39: =SUMIFS(Leads_Canal!$C$4:$C$503,Leads_Canal!$A$4:$A$503,$E$3,Leads_Canal!$B$4:$B$503,Config!$I$13) -> 7 | E39: =C39-D39 -> 1 | F39: =IF(SUM($C$36:$C$44)=0,"",C39/SUM($C$36:$C$44)) -> 0.17777778
B40: =Config!$I$14 -> Facebook | C40: =SUMIFS(Leads_Canal!$C$4:$C$503,Leads_Canal!$A$4:$A$503,$C$3,Leads_Canal!$B$4:$B$503,Config!$I$14) -> 0 | D40: =SUMIFS(Leads_Canal!$C$4:$C$503,Leads_Canal!$A$4:$A$503,$E$3,Leads_Canal!$B$4:$B$503,Config!$I$14) -> 0 | E40: =C40-D40 -> 0 | F40: =IF(SUM($C$36:$C$44)=0,"",C40/SUM($C$36:$C$44)) -> 0
B41: =Config!$I$15 -> Site | C41: =SUMIFS(Leads_Canal!$C$4:$C$503,Leads_Canal!$A$4:$A$503,$C$3,Leads_Canal!$B$4:$B$503,Config!$I$15) -> 0 | D41: =SUMIFS(Leads_Canal!$C$4:$C$503,Leads_Canal!$A$4:$A$503,$E$3,Leads_Canal!$B$4:$B$503,Config!$I$15) -> 0 | E41: =C41-D41 -> 0 | F41: =IF(SUM($C$36:$C$44)=0,"",C41/SUM($C$36:$C$44)) -> 0
B42: =Config!$I$16 -> Convênio/Parceria | C42: =SUMIFS(Leads_Canal!$C$4:$C$503,Leads_Canal!$A$4:$A$503,$C$3,Leads_Canal!$B$4:$B$503,Config!$I$16) -> 0 | D42: =SUMIFS(Leads_Canal!$C$4:$C$503,Leads_Canal!$A$4:$A$503,$E$3,Leads_Canal!$B$4:$B$503,Config!$I$16) -> 0 | E42: =C42-D42 -> 0 | F42: =IF(SUM($C$36:$C$44)=0,"",C42/SUM($C$36:$C$44)) -> 0
B43: =Config!$I$17 -> Passante/Fachada | C43: =SUMIFS(Leads_Canal!$C$4:$C$503,Leads_Canal!$A$4:$A$503,$C$3,Leads_Canal!$B$4:$B$503,Config!$I$17) -> 0 | D43: =SUMIFS(Leads_Canal!$C$4:$C$503,Leads_Canal!$A$4:$A$503,$E$3,Leads_Canal!$B$4:$B$503,Config!$I$17) -> 0 | E43: =C43-D43 -> 0 | F43: =IF(SUM($C$36:$C$44)=0,"",C43/SUM($C$36:$C$44)) -> 0
...

Sheet Config
A1: Configurações, metas e listas
A2: Células amarelas: preencher. As listas alimentam os menus (validação) das abas de coleta.
A4: Equipe
A5: Fisio 1 | B5: Ariosto
A6: Fisio 2 | B6: Tássia
A8: Metas
A9: Indicador | B9: Meta semanal | C9: Meta mensal | E9: Tipo de contrato | F9: Condição de pagamento | G9: Forma de pagamento | H9: Status de pagamento | I9: Canal de ingresso | J9: Categoria financeira | K9: Tipo de custo | L9: Status da ação | M9: Resultado geral | N9: Sim/Não | O9: Fisioterapeuta
A10: Leads recebidos | B10: 40 | C10: 170 | E10: Avaliação | F10: À vista | G10: Pix | H10: Pago | I10: Instagram | J10: Receita | K10: Fixo | L10: A fazer | M10: Melhor | N10: Sim | O10: =$B$5 -> Ariosto
A11: Novos pacientes | B11: 8 | C11: 32 | E11: Protocolo | F11: Parcelado | G11: Dinheiro | H11: Pendente | I11: Google | J11: Gasto | K11: Variável | L11: Em andamento | M11: Igual | N11: Não | O11: =$B$6 -> Tássia
A12: Avaliações realizadas | B12: 12 | C12: 50 | G12: Cartão de débito | H12: Atrasado | I12: WhatsApp direto | J12: Imposto | L12: Concluída | M12: Pior
A13: Contratos fechados (tratamentos) | B13: 8 | C13: 32 | G13: Cartão de crédito | H13: Cancelado | I13: Indicação | J13: Marketing | L13: Cancelada
A14: Atendimentos realizados | B14: 120 | C14: 500 | G14: Boleto | I14: Facebook
A15: Taxa de ocupação da agenda | B15: 0.85 | C15: 0.85 | G15: Transferência | I15: Site
A16: Receita | B16: 30000 | C16: 120000 | G16: Convênio | I16: Convênio/Parceria
A17: Gastos | B17: 18000 | C17: 72000 | I17: Passante/Fachada
A18: Investimento em marketing | B18: 2500 | C18: 10000 | I18: Outro
A19: Conversão avaliação → contrato | B19: 0.6 | C19: 0.6
A20: Taxa máx. de cancelamento de avaliações | B20: 0.15 | C20: 0.15
A21: Metas são valores de referência informados pelo usuário; ajuste conforme o planejamento da clínica.

Sheet Calendario
A1: Calendário de semanas
A2: Semanas ISO (segunda a domingo). O mês da semana é o mês da data de início.
A3: id_semana | B3: Início | C3: Fim | D3: Mês
A4: 2026-S02 | B4: 46027 | C4: 46033 | D4: 2026-01
A5: 2026-S03 | B5: 46034 | C5: 46040 | D5: 2026-01
A6: 2026-S04 | B6: 46041 | C6: 46047 | D6: 2026-01
A7: 2026-S05 | B7: 46048 | C7: 46054 | D7: 2026-01
A8: 2026-S06 | B8: 46055 | C8: 46061 | D8: 2026-02
A9: 2026-S07 | B9: 46062 | C9: 46068 | D9: 2026-02
A10: 2026-S08 | B10: 46069 | C10: 46075 | D10: 2026-02
A11: 2026-S09 | B11: 46076 | C11: 46082 | D11: 2026-02
A12: 2026-S10 | B12: 46083 | C12: 46089 | D12: 2026-03
A13: 2026-S11 | B13: 46090 | C13: 46096 | D13: 2026-03
A14: 2026-S12 | B14: 46097 | C14: 46103 | D14: 2026-03
A15: 2026-S13 | B15: 46104 | C15: 46110 | D15: 2026-03
... A107: 2027-S52 | B107: 46748 | C107: 46754 | D107: 2027-12

Sheet Base_Semanal
A1: Base de dados semanal (coleta)
A2: Preencha as colunas amarelas; uma linha por semana. As três primeiras colunas de datas são automáticas.
A3: id_semana | B3: Início | C3: Fim | D3: Mês | E3: Leads recebidos | F3: Aval. agendadas | G3: Aval. canceladas | H3: Aval. realizadas Fisio 1 | I3: Aval. realizadas Fisio 2 | J3: Contratos fechados Fisio 1 | K3: Contratos fechados Fisio 2 | L3: Atendimentos Fisio 1 | M3: Atendimentos Fisio 2 | N3: Cancelamentos de atendimentos | O3: Novos pacientes | P3: Horários disponíveis manhã | Q3: Horários ocupados manhã | R3: Horários disponíveis tarde | S3: Horários ocupados tarde | T3: Tempo médio atend. Fisio 1 (min) | U3: Desvio padrão Fisio 1 (min) | V3: Tempo médio atend. Fisio 2 (min) | W3: Desvio padrão Fisio 2 (min) | X3: Observações
A4: 2026-S02 | B4: =IFERROR(INDEX(Calendario!$B$4:$B$107,MATCH($A4,Calendario!$A$4:$A$107,0)),"") -> 46027 | C4: =IFERROR(INDEX(Calendario!$C$4:$C$107,MATCH($A4,Calendario!$A$4:$A$107,0)),"") -> 46033 | D4: =IFERROR(INDEX(Calendario!$D$4:$D$107,MATCH($A4,Calendario!$A$4:$A$107,0)),"") -> 2026-01
A5: 2026-S03 | B5: =IFERROR(INDEX(Calendario!$B$4:$B$107,MATCH($A5,Calendario!$A$4:$A$107,0)),"") -> 46034 | C5: =IFERROR(INDEX(Calendario!$C$4:$C$107,MATCH($A5,Calendario!$A$4:$A$107,0)),"") -> 46040 | D5: =IFERROR(INDEX(Calendario!$D$4:$D$107,MATCH($A5,Calendario!$A$4:$A$107,0)),"") -> 2026-01
A6: 2026-S04 | B6: =IFERROR(INDEX(Calendario!$B$4:$B$107,MATCH($A6,Calendario!$A$4:$A$107,0)),"") -> 46041 | C6: =IFERROR(INDEX(Calendario!$C$4:$C$107,MATCH($A6,Calendario!$A$4:$A$107,0)),"") -> 46047 | D6: =IFERROR(INDEX(Calendario!$D$4:$D$107,MATCH($A6,Calendario!$A$4:$A$107,0)),"") -> 2026-01
A7: 2026-S05 | B7: =IFERROR(INDEX(Calendario!$B$4:$B$107,MATCH($A7,Calendario!$A$4:$A$107,0)),"") -> 46048 | C7: =IFERROR(INDEX(Calendario!$C$4:$C$107,MATCH($A7,Calendario!$A$4:$A$107,0)),"") -> 46054 | D7: =IFERROR(INDEX(Calendario!$D$4:$D$107,MATCH($A7,Calendario!$A$4:$A$107,0)),"") -> 2026-01
A8: 2026-S06 | B8: =IFERROR(INDEX(Calendario!$B$4:$B$107,MATCH($A8,Calendario!$A$4:$A$107,0)),"") -> 46055 | C8: =IFERROR(INDEX(Calendario!$C$4:$C$107,MATCH($A8,Calendario!$A$4:$A$107,0)),"") -> 46061 | D8: =IFERROR(INDEX(Calendario!$D$4:$D$107,MATCH($A8,Calendario!$A$4:$A$107,0)),"") -> 2026-02
A9: 2026-S07 | B9: =IFERROR(INDEX(Calendario!$B$4:$B$107,MATCH($A9,Calendario!$A$4:$A$107,0)),"") -> 46062 | C9: =IFERROR(INDEX(Calendario!$C$4:$C$107,MATCH($A9,Calendario!$A$4:$A$107,0)),"") -> 46068 | D9: =IFERROR(INDEX(Calendario!$D$4:$D$107,MATCH($A9,Calendario!$A$4:$A$107,0)),"") -> 2026-02
A10: 2026-S08 | B10: =IFERROR(INDEX(Calendario!$B$4:$B$107,MATCH($A10,Calendario!$A$4:$A$107,0)),"") -> 46069 | C10: =IFERROR(INDEX(Calendario!$C$4:$C$107,MATCH($A10,Calendario!$A$4:$A$107,0)),"") -> 46075 | D10: =IFERROR(INDEX(Calendario!$D$4:$D$107,MATCH($A10,Calendario!$A$4:$A$107,0)),"") -> 2026-02
A11: 2026-S09 | B11: =IFERROR(INDEX(Calendario!$B$4:$B$107,MATCH($A11,Calendario!$A$4:$A$107,0)),"") -> 46076 | C11: =IFERROR(INDEX(Calendario!$C$4:$C$107,MATCH($A11,Calendario!$A$4:$A$107,0)),"") -> 46082 | D11: =IFERROR(INDEX(Calendario!$D$4:$D$107,MATCH($A11,Calendario!$A$4:$A$107,0)),"") -> 2026-02
A12: 2026-S10 | B12: =IFERROR(INDEX(Calendario!$B$4:$B$107,MATCH($A12,Calendario!$A$4:$A$107,0)),"") -> 46083 | C12: =IFERROR(INDEX(Calendario!$C$4:$C$107,MATCH($A12,Calendario!$A$4:$A$107,0)),"") -> 46089 | D12: =IFERROR(INDEX(Calendario!$D$4:$D$107,MATCH($A12,Calendario!$A$4:$A$107,0)),"") -> 2026-03
A13: 2026-S11 | B13: =IFERROR(INDEX(Calendario!$B$4:$B$107,MATCH($A13,Calendario!$A$4:$A$107,0)),"") -> 46090 | C13: =IFERROR(INDEX(Calendario!$C$4:$C$107,MATCH($A13,Calendario!$A$4:$A$107,0)),"") -> 46096 | D13: =IFERROR(INDEX(Calendario!$D$4:$D$107,MATCH($A13,Calendario!$A$4:$A$107,0)),"") -> 2026-03
A14: 2026-S12 | B14: =IFERROR(INDEX(Calendario!$B$4:$B$107,MATCH($A14,Calendario!$A$4:$A$107,0)),"") -> 46097 | C14: =IFERROR(INDEX(Calendario!$C$4:$C$107,MATCH($A14,Calendario!$A$4:$A$107,0)),"") -> 46103 | D14: =IFERROR(INDEX(Calendario!$D$4:$D$107,MATCH($A14,Calendario!$A$4:$A$107,0)),"") -> 2026-03
A15: 2026-S13 | B15: =IFERROR(INDEX(Calendario!$B$4:$B$107,MATCH($A15,Calendario!$A$4:$A$107,0)),"") -> 46104 | C15: =IFERROR(INDEX(Calendario!$C$4:$C$107,MATCH($A15,Calendario!$A$4:$A$107,0)),"") -> 46110 | D15: =IFERROR(INDEX(Calendario!$D$4:$D$107,MATCH($A15,Calendario!$A$4:$A$107,0)),"") -> 2026-03
... A40: 2026-S38 | B40: =IFERROR(INDEX(Calendario!$B$4:$B$107,MATCH($A40,Calendario!$A$4:$A$107,0)),"") -> 46279 | C40: =IFERROR(INDEX(Calendario!$C$4:$C$107,MATCH($A40,Calendario!$A$4:$A$107,0)),"") -> 46285 | D40: =IFERROR(INDEX(Calendario!$D$4:$D$107,MATCH($A40,Calendario!$A$4:$A$107,0)),"") -> 2026-09
A41: 2026-S39 | B41: =IFERROR(INDEX(Calendario!$B$4:$B$107,MATCH($A41,Calendario!$A$4:$A$107,0)),"") -> 46286 | C41: =IFERROR(INDEX(Calendario!$C$4:$C$107,MATCH($A41,Calendario!$A$4:$A$107,0)),"") -> 46292 | D41: =IFERROR(INDEX(Calendario!$D$4:$D$107,MATCH($A41,Calendario!$A$4:$A$107,0)),"") -> 2026-09 | E41: 38 | F41: 14 | G41: 2 | H41: 6 | I41: 5 | J41: 4 | K41: 3 | L41: 58 | M41: 52 | N41: 7 | O41: 6 | P41: 60 | Q41: 54 | R41: 60 | S41: 50 | T41: 42.5 | U41: 6.1 | V41: 39.8 | W41: 5.4 | X41: Exemplo — substitua pelos dados reais
A42: 2026-S40 | B42: =IFERROR(INDEX(Calendario!$B$4:$B$107,MATCH($A42,Calendario!$A$4:$A$107,0)),"") -> 46293 | C42: =IFERROR(INDEX(Calendario!$C$4:$C$107,MATCH($A42,Calendario!$A$4:$A$107,0)),"") -> 46299 | D42: =IFERROR(INDEX(Calendario!$D$4:$D$107,MATCH($A42,Calendario!$A$4:$A$107,0)),"") -> 2026-09 | E42: 45 | F42: 16 | G42: 1 | H42: 8 | I42: 6 | J42: 6 | K42: 4 | L42: 63 | M42: 57 | N42: 5 | O42: 9 | P42: 60 | Q42: 57 | R42: 60 | S42: 55 | T42: 41.2 | U42: 5.8 | V42: 40.5 | W42: 4.9 | X42: Exemplo — substitua pelos dados reais
A43: 2026-S41 | B43: =IFERROR(INDEX(Calendario!$B$4:$B$107,MATCH($A43,Calendario!$A$4:$A$107,0)),"") -> 46300 | C43: =IFERROR(INDEX(Calendario!$C$4:$C$107,MATCH($A43,Calendario!$A$4:$A$107,0)),"") -> 46306 | D43: =IFERROR(INDEX(Calendario!$D$4:$D$107,MATCH($A43,Calendario!$A$4:$A$107,0)),"") -> 2026-10 | P43: 60 | Q43: 44 | R43: 60 | S43: 38 | X43: Exemplo — agenda já ocupada para a próxima semana
A44: 2026-S42 | B44: =IFERROR(INDEX(Calendario!$B$4:$B$107,MATCH($A44,Calendario!$A$4:$A$107,0)),"") -> 46307 | C44: =IFERROR(INDEX(Calendario!$C$4:$C$107,MATCH($A44,Calendario!$A$4:$A$107,0)),"") -> 46313 | D44: =IFERROR(INDEX(Calendario!$D$4:$D$107,MATCH($A44,Calendario!$A$4:$A$107,0)),"") -> 2026-10
A45: 2026-S43 | B45: =IFERROR(INDEX(Calendario!$B$4:$B$107,MATCH($A45,Calendario!$A$4:$A$107,0)),"") -> 46314 | C45: =IFERROR(INDEX(Calendario!$C$4:$C$107,MATCH($A45,Calendario!$A$4:$A$107,0)),"") -> 46320 | D45: =IFERROR(INDEX(Calendario!$D$4:$D$107,MATCH($A45,Calendario!$A$4:$A$107,0)),"") -> 2026-10
A46: 2026-S44 | B46: =IFERROR(INDEX(Calendario!$B$4:$B$107,MATCH($A46,Calendario!$A$4:$A$107,0)),"") -> 46321 | C46: =IFERROR(INDEX(Calendario!$C$4:$C$107,MATCH($A46,Calendario!$A$4:$A$107,0)),"") -> 46327 | D46: =IFERROR(INDEX(Calendario!$D$4:$D$107,MATCH($A46,Calendario!$A$4:$A$107,0)),"") -> 2026-10
A47: 2026-S45 | B47: =IFERROR(INDEX(Calendario!$B$4:$B$107,MATCH($A47,Calendario!$A$4:$A$107,0)),"") -> 46328 | C47: =IFERROR(INDEX(Calendario!$C$4:$C$107,MATCH($A47,Calendario!$A$4:$A$107,0)),"") -> 46334 | D47: =IFERROR(INDEX(Calendario!$D$4:$D$107,MATCH($A47,Calendario!$A$4:$A$107,0)),"") -> 2026-11
A48: 2026-S46 | B48: =IFERROR(INDEX(Calendario!$B$4:$B$107,MATCH($A48,Calendario!$A$4:$A$107,0)),"") -> 46335 | C48: =IFERROR(INDEX(Calendario!$C$4:$C$107,MATCH($A48,Calendario!$A$4:$A$107,0)),"") -> 46341 | D48: =IFERROR(INDEX(Calendario!$D$4:$D$107,MATCH($A48,Calendario!$A$4:$A$107,0)),"") -> 2026-11
A49: 2026-S47 | B49: =IFERROR(INDEX(Calendario!$B$4:$B$107,MATCH($A49,Calendario!$A$4:$A$107,0)),"") -> 46342 | C49: =IFERROR(INDEX(Calendario!$C$4:$C$107,MATCH($A49,Calendario!$A$4:$A$107,0)),"") -> 46348 | D49: =IFERROR(INDEX(Calendario!$D$4:$D$107,MATCH($A49,Calendario!$A$4:$A$107,0)),"") -> 2026-11
A50: 2026-S48 | B50: =IFERROR(INDEX(Calendario!$B$4:$B$107,MATCH($A50,Calendario!$A$4:$A$107,0)),"") -> 46349 | C50: =IFERROR(INDEX(Calendario!$C$4:$C$107,MATCH($A50,Calendario!$A$4:$A$107,0)),"") -> 46355 | D50: =IFERROR(INDEX(Calendario!$D$4:$D$107,MATCH($A50,Calendario!$A$4:$A$107,0)),"") -> 2026-11
A51: 2026-S49 | B51: =IFERROR(INDEX(Calendario!$B$4:$B$107,MATCH($A51,Calendario!$A$4:$A$107,0)),"") -> 46356 | C51: =IFERROR(INDEX(Calendario!$C$4:$C$107,MATCH($A51,Calendario!$A$4:$A$107,0)),"") -> 46362 | D51: =IFERROR(INDEX(Calendario!$D$4:$D$107,MATCH($A51,Calendario!$A$4:$A$107,0)),"") -> 2026-11
A52: 2026-S50 | B52: =IFERROR(INDEX(Calendario!$B$4:$B$107,MATCH($A52,Calendario!$A$4:$A$107,0)),"") -> 46363 | C52: =IFERROR(INDEX(Calendario!$C$4:$C$107,MATCH($A52,Calendario!$A$4:$A$107,0)),"") -> 46369 | D52: =IFERROR(INDEX(Calendario!$D$4:$D$107,MATCH($A52,Calendario!$A$4:$A$107,0)),"") -> 2026-12
A53: 2026-S51 | B53: =IFERROR(INDEX(Calendario!$B$4:$B$107,MATCH($A53,Calendario!$A$4:$A$107,0)),"") -> 46370 | C53: =IFERROR(INDEX(Calendario!$C$4:$C$107,MATCH($A53,Calendario!$A$4:$A$107,0)),"") -> 46376 | D53: =IFERROR(INDEX(Calendario!$D$4:$D$107,MATCH($A53,Calendario!$A$4:$A$107,0)),"") -> 2026-12
A54: 2026-S52 | B54: =IFERROR(INDEX(Calendario!$B$4:$B$107,MATCH($A54,Calendario!$A$4:$A$107,0)),"") -> 46377 | C54: =IFERROR(INDEX(Calendario!$C$4:$C$107,MATCH($A54,Calendario!$A$4:$A$107,0)),"") -> 46383 | D54: =IFERROR(INDEX(Calendario!$D$4:$D$107,MATCH($A54,Calendario!$A$4:$A$107,0)),"") -> 2026-12
A55: 2026-S53 | B55: =IFERROR(INDEX(Calendario!$B$4:$B$107,MATCH($A55,Calendario!$A$4:$A$107,0)),"") -> 46384 | C55: =IFERROR(INDEX(Calendario!$C$4:$C$107,MATCH($A55,Calendario!$A$4:$A$107,0)),"") -> 46390 | D55: =IFERROR(INDEX(Calendario!$D$4:$D$107,MATCH($A55,Calendario!$A$4:$A$107,0)),"") -> 2026-12
... A107: 2027-S52 | B107: =IFERROR(INDEX(Calendario!$B$4:$B$107,MATCH($A107,Calendario!$A$4:$A$107,0)),"") -> 46748 | C107: =IFERROR(INDEX(Calendario!$C$4:$C$107,MATCH($A107,Calendario!$A$4:$A$107,0)),"") -> 46754 | D107: =IFERROR(INDEX(Calendario!$D$4:$D$107,MATCH($A107,Calendario!$A$4:$A$107,0)),"") -> 2027-12

Sheet Contratos
A1: Avaliações e protocolos contratados
A2: Uma linha por contrato fechado. Semana e mês são calculados pela data.
A3: Data | B3: id_semana | C3: Mês | D3: Paciente | E3: Tipo | F3: Fisioterapeuta | G3: Protocolo / descrição | H3: Nº sessões | I3: Valor (R$) | J3: Condição de pagamento | K3: Forma de pagamento | L3: Parcelas | M3: Status pagamento | N3: Canal de ingresso | O3: Observações
A4: 46287 | B4: =IF(A4="","",IFERROR(INDEX(Calendario!$A$4:$A$107,MATCH(A4,Calendario!$B$4:$B$107,1)),"")) -> 2026-S39 | C4: =IF(A4="","",YEAR(A4)&"-"&TEXT(MONTH(A4),"00")) -> 2026-09 | D4: Maria S. (exemplo) | E4: Avaliação | F4: Ariosto | G4: Avaliação inicial coluna | H4: 1 | I4: 150 | J4: À vista | K4: Pix | L4: 1 | M4: Pago | N4: Instagram | O4: Exemplo — substitua pelos dados reais
A5: 46288 | B5: =IF(A5="","",IFERROR(INDEX(Calendario!$A$4:$A$107,MATCH(A5,Calendario!$B$4:$B$107,1)),"")) -> 2026-S39 | C5: =IF(A5="","",YEAR(A5)&"-"&TEXT(MONTH(A5),"00")) -> 2026-09 | D5: João P. (exemplo) | E5: Protocolo | F5: Tássia | G5: Protocolo hérnia lombar — 20 sessões | H5: 20 | I5: 3800 | J5: Parcelado | K5: Cartão de crédito | L5: 6 | M5: Pago | N5: Google | O5: Exemplo — substitua pelos dados reais
A6: 46290 | B6: =IF(A6="","",IFERROR(INDEX(Calendario!$A$4:$A$107,MATCH(A6,Calendario!$B$4:$B$107,1)),"")) -> 2026-S39 | C6: =IF(A6="","",YEAR(A6)&"-"&TEXT(MONTH(A6),"00")) -> 2026-09 | D6: Carla M. (exemplo) | E6: Protocolo | F6: Ariosto | G6: Protocolo cervical — 12 sessões | H6: 12 | I6: 2400 | J6: À vista | K6: Pix | L6: 1 | M6: Pago | N6: Indicação | O6: Exemplo — substitua pelos dados reais
A7: 46294 | B7: =IF(A7="","",IFERROR(INDEX(Calendario!$A$4:$A$107,MATCH(A7,Calendario!$B$4:$B$107,1)),"")) -> 2026-S40 | C7: =IF(A7="","",YEAR(A7)&"-"&TEXT(MONTH(A7),"00")) -> 2026-09 | D7: Pedro L. (exemplo) | E7: Avaliação | F7: Tássia | G7: Avaliação inicial | H7: 1 | I7: 150 | J7: À vista | K7: Dinheiro | L7: 1 | M7: Pago | N7: WhatsApp direto | O7: Exemplo — substitua pelos dados reais
A8: 46295 | B8: =IF(A8="","",IFERROR(INDEX(Calendario!$A$4:$A$107,MATCH(A8,Calendario!$B$4:$B$107,1)),"")) -> 2026-S40 | C8: =IF(A8="","",YEAR(A8)&"-"&TEXT(MONTH(A8),"00")) -> 2026-09 | D8: Ana R. (exemplo) | E8: Protocolo | F8: Ariosto | G8: Protocolo hérnia lombar — 20 sessões | H8: 20 | I8: 3800 | J8: Parcelado | K8: Boleto | L8: 4 | M8: Pendente | N8: Instagram | O8: Exemplo — substitua pelos dados reais
A9: 46296 | B9: =IF(A9="","",IFERROR(INDEX(Calendario!$A$4:$A$107,MATCH(A9,Calendario!$B$4:$B$107,1)),"")) -> 2026-S40 | C9: =IF(A9="","",YEAR(A9)&"-"&TEXT(MONTH(A9),"00")) -> 2026-10 | D9: Lucas F. (exemplo) | E9: Protocolo | F9: Tássia | G9: Protocolo joelho — 16 sessões | H9: 16 | I9: 3000 | J9: Parcelado | K9: Cartão de crédito | L9: 3 | M9: Pago | N9: Indicação | O9: Exemplo — substitua pelos dados reais
A10: 46297 | B10: =IF(A10="","",IFERROR(INDEX(Calendario!$A$4:$A$107,MATCH(A10,Calendario!$B$4:$B$107,1)),"")) -> 2026-S40 | C10: =IF(A10="","",YEAR(A10)&"-"&TEXT(MONTH(A10),"00")) -> 2026-10 | D10: Beatriz C. (exemplo) | E10: Avaliação | F10: Ariosto | G10: Avaliação inicial | H10: 1 | I10: 150 | J10: À vista | K10: Pix | L10: 1 | M10: Pago | N10: Google | O10: Exemplo — substitua pelos dados reais
B11: =IF(A11="","",IFERROR(INDEX(Calendario!$A$4:$A$107,MATCH(A11,Calendario!$B$4:$B$107,1)),"")) | C11: =IF(A11="","",YEAR(A11)&"-"&TEXT(MONTH(A11),"00"))
B12: =IF(A12="","",IFERROR(INDEX(Calendario!$A$4:$A$107,MATCH(A12,Calendario!$B$4:$B$107,1)),"")) | C12: =IF(A12="","",YEAR(A12)&"-"&TEXT(MONTH(A12),"00"))
B13: =IF(A13="","",IFERROR(INDEX(Calendario!$A$4:$A$107,MATCH(A13,Calendario!$B$4:$B$107,1)),"")) | C13: =IF(A13="","",YEAR(A13)&"-"&TEXT(MONTH(A13),"00"))
B14: =IF(A14="","",IFERROR(INDEX(Calendario!$A$4:$A$107,MATCH(A14,Calendario!$B$4:$B$107,1)),"")) | C14: =IF(A14="","",YEAR(A14)&"-"&TEXT(MONTH(A14),"00"))
B15: =IF(A15="","",IFERROR(INDEX(Calendario!$A$4:$A$107,MATCH(A15,Calendario!$B$4:$B$107,1)),"")) | C15: =IF(A15="","",YEAR(A15)&"-"&TEXT(MONTH(A15),"00"))
B16: =IF(A16="","",IFERROR(INDEX(Calendario!$A$4:$A$107,MATCH(A16,Calendario!$B$4:$B$107,1)),"")) | C16: =IF(A16="","",YEAR(A16)&"-"&TEXT(MONTH(A16),"00"))
B17: =IF(A17="","",IFERROR(INDEX(Calendario!$A$4:$A$107,MATCH(A17,Calendario!$B$4:$B$107,1)),"")) | C17: =IF(A17="","",YEAR(A17)&"-"&TEXT(MONTH(A17),"00"))
B18: =IF(A18="","",IFERROR(INDEX(Calendario!$A$4:$A$107,MATCH(A18,Calendario!$B$4:$B$107,1)),"")) | C18: =IF(A18="","",YEAR(A18)&"-"&TEXT(MONTH(A18),"00"))
B19: =IF(A19="","",IFERROR(INDEX(Calendario!$A$4:$A$107,MATCH(A19,Calendario!$B$4:$B$107,1)),"")) | C19: =IF(A19="","",YEAR(A19)&"-"&TEXT(MONTH(A19),"00"))
B20: =IF(A20="","",IFERROR(INDEX(Calendario!$A$4:$A$107,MATCH(A20,Calendario!$B$4:$B$107,1)),"")) | C20: =IF(A20="","",YEAR(A20)&"-"&TEXT(MONTH(A20),"00"))
B21: =IF(A21="","",IFERROR(INDEX(Calendario!$A$4:$A$107,MATCH(A21,Calendario!$B$4:$B$107,1)),"")) | C21: =IF(A21="","",YEAR(A21)&"-"&TEXT(MONTH(A21),"00"))
B22: =IF(A22="","",IFERROR(INDEX(Calendario!$A$4:$A$107,MATCH(A22,Calendario!$B$4:$B$107,1)),"")) | C22: =IF(A22="","",YEAR(A22)&"-"&TEXT(MONTH(A22),"00"))
... B503: =IF(A503="","",IFERROR(INDEX(Calendario!$A$4:$A$107,MATCH(A503,Calendario!$B$4:$B$107,1)),"")) | C503: =IF(A503="","",YEAR(A503)&"-"&TEXT(MONTH(A503),"00"))

Sheet Financeiro
A1: Financeiro (lançamentos)
A2: Uma linha por receita, gasto, imposto ou investimento em marketing. Receitas com status Pendente = pendências; Atrasado = inadimplência.
A3: Data | B3: id_semana | C3: Mês | D3: Categoria | E3: Tipo de custo | F3: Descrição | G3: Valor (R$) | H3: Status | I3: Vencimento | J3: Paciente / fornecedor | K3: Observações
A4: 46287 | B4: =IF(A4="","",IFERROR(INDEX(Calendario!$A$4:$A$107,MATCH(A4,Calendario!$B$4:$B$107,1)),"")) -> 2026-S39 | C4: =IF(A4="","",YEAR(A4)&"-"&TEXT(MONTH(A4),"00")) -> 2026-09 | D4: Receita | F4: Avaliação — Maria S. | G4: 150 | H4: Pago | I4: 46287 | J4: Maria S. | K4: Exemplo — substitua pelos dados reais
A5: 46288 | B5: =IF(A5="","",IFERROR(INDEX(Calendario!$A$4:$A$107,MATCH(A5,Calendario!$B$4:$B$107,1)),"")) -> 2026-S39 | C5: =IF(A5="","",YEAR(A5)&"-"&TEXT(MONTH(A5),"00")) -> 2026-09 | D5: Receita | F5: Protocolo — João P. (1/6) | G5: 633.33 | H5: Pago | I5: 46288 | J5: João P. | K5: Exemplo — substitua pelos dados reais
A6: 46290 | B6: =IF(A6="","",IFERROR(INDEX(Calendario!$A$4:$A$107,MATCH(A6,Calendario!$B$4:$B$107,1)),"")) -> 2026-S39 | C6: =IF(A6="","",YEAR(A6)&"-"&TEXT(MONTH(A6),"00")) -> 2026-09 | D6: Receita | F6: Protocolo — Carla M. | G6: 2400 | H6: Pago | I6: 46290 | J6: Carla M. | K6: Exemplo — substitua pelos dados reais
A7: 46290 | B7: =IF(A7="","",IFERROR(INDEX(Calendario!$A$4:$A$107,MATCH(A7,Calendario!$B$4:$B$107,1)),"")) -> 2026-S39 | C7: =IF(A7="","",YEAR(A7)&"-"&TEXT(MONTH(A7),"00")) -> 2026-09 | D7: Gasto | E7: Fixo | F7: Folha de pagamento — recepção | G7: 2800 | H7: Pago | I7: 46290 | J7: Equipe | K7: Exemplo — substitua pelos dados reais
A8: 46291 | B8: =IF(A8="","",IFERROR(INDEX(Calendario!$A$4:$A$107,MATCH(A8,Calendario!$B$4:$B$107,1)),"")) -> 2026-S39 | C8: =IF(A8="","",YEAR(A8)&"-"&TEXT(MONTH(A8),"00")) -> 2026-09 | D8: Marketing | F8: Impulsionamento Instagram | G8: 600 | H8: Pago | I8: 46291 | J8: Meta Ads | K8: Exemplo — substitua pelos dados reais
A9: 46294 | B9: =IF(A9="","",IFERROR(INDEX(Calendario!$A$4:$A$107,MATCH(A9,Calendario!$B$4:$B$107,1)),"")) -> 2026-S40 | C9: =IF(A9="","",YEAR(A9)&"-"&TEXT(MONTH(A9),"00")) -> 2026-09 | D9: Receita | F9: Avaliação — Pedro L. | G9: 150 | H9: Pago | I9: 46294 | J9: Pedro L. | K9: Exemplo — substitua pelos dados reais
A10: 46295 | B10: =IF(A10="","",IFERROR(INDEX(Calendario!$A$4:$A$107,MATCH(A10,Calendario!$B$4:$B$107,1)),"")) -> 2026-S40 | C10: =IF(A10="","",YEAR(A10)&"-"&TEXT(MONTH(A10),"00")) -> 2026-09 | D10: Receita | F10: Protocolo — Ana R. (1/4) | G10: 950 | H10: Pendente | I10: 46305 | J10: Ana R. | K10: Exemplo — substitua pelos dados reais
A11: 46296 | B11: =IF(A11="","",IFERROR(INDEX(Calendario!$A$4:$A$107,MATCH(A11,Calendario!$B$4:$B$107,1)),"")) -> 2026-S40 | C11: =IF(A11="","",YEAR(A11)&"-"&TEXT(MONTH(A11),"00")) -> 2026-10 | D11: Receita | F11: Protocolo — Lucas F. (1/3) | G11: 1000 | H11: Pago | I11: 46296 | J11: Lucas F. | K11: Exemplo — substitua pelos dados reais
A12: 46296 | B12: =IF(A12="","",IFERROR(INDEX(Calendario!$A$4:$A$107,MATCH(A12,Calendario!$B$4:$B$107,1)),"")) -> 2026-S40 | C12: =IF(A12="","",YEAR(A12)&"-"&TEXT(MONTH(A12),"00")) -> 2026-10 | D12: Gasto | E12: Fixo | F12: Aluguel | G12: 4500 | H12: Pago | I12: 46296 | J12: Imobiliária | K12: Exemplo — substitua pelos dados reais
A13: 46296 | B13: =IF(A13="","",IFERROR(INDEX(Calendario!$A$4:$A$107,MATCH(A13,Calendario!$B$4:$B$107,1)),"")) -> 2026-S40 | C13: =IF(A13="","",YEAR(A13)&"-"&TEXT(MONTH(A13),"00")) -> 2026-10 | D13: Gasto | E13: Variável | F13: Material de consumo (bandagens, eletrodos) | G13: 380 | H13: Pago | I13: 46296 | J13: Fornecedor | K13: Exemplo — substitua pelos dados reais
A14: 46297 | B14: =IF(A14="","",IFERROR(INDEX(Calendario!$A$4:$A$107,MATCH(A14,Calendario!$B$4:$B$107,1)),"")) -> 2026-S40 | C14: =IF(A14="","",YEAR(A14)&"-"&TEXT(MONTH(A14),"00")) -> 2026-10 | D14: Imposto | F14: Simples Nacional — DAS | G14: 1850 | H14: Pago | I14: 46315 | J14: Receita Federal | K14: Exemplo — substitua pelos dados reais
A15: 46297 | B15: =IF(A15="","",IFERROR(INDEX(Calendario!$A$4:$A$107,MATCH(A15,Calendario!$B$4:$B$107,1)),"")) -> 2026-S40 | C15: =IF(A15="","",YEAR(A15)&"-"&TEXT(MONTH(A15),"00")) -> 2026-10 | D15: Marketing | F15: Google Ads | G15: 700 | H15: Pago | I15: 46297 | J15: Google | K15: Exemplo — substitua pelos dados reais
A16: 46297 | B16: =IF(A16="","",IFERROR(INDEX(Calendario!$A$4:$A$107,MATCH(A16,Calendario!$B$4:$B$107,1)),"")) -> 2026-S40 | C16: =IF(A16="","",YEAR(A16)&"-"&TEXT(MONTH(A16),"00")) -> 2026-10 | D16: Receita | F16: Protocolo — Roberto A. (2/5) | G16: 760 | H16: Atrasado | I16: 46280 | J16: Roberto A. | K16: Exemplo — substitua pelos dados reais
B17: =IF(A17="","",IFERROR(INDEX(Calendario!$A$4:$A$107,MATCH(A17,Calendario!$B$4:$B$107,1)),"")) | C17: =IF(A17="","",YEAR(A17)&"-"&TEXT(MONTH(A17),"00"))
B18: =IF(A18="","",IFERROR(INDEX(Calendario!$A$4:$A$107,MATCH(A18,Calendario!$B$4:$B$107,1)),"")) | C18: =IF(A18="","",YEAR(A18)&"-"&TEXT(MONTH(A18),"00"))
B19: =IF(A19="","",IFERROR(INDEX(Calendario!$A$4:$A$107,MATCH(A19,Calendario!$B$4:$B$107,1)),"")) | C19: =IF(A19="","",YEAR(A19)&"-"&TEXT(MONTH(A19),"00"))
B20: =IF(A20="","",IFERROR(INDEX(Calendario!$A$4:$A$107,MATCH(A20,Calendario!$B$4:$B$107,1)),"")) | C20: =IF(A20="","",YEAR(A20)&"-"&TEXT(MONTH(A20),"00"))
B21: =IF(A21="","",IFERROR(INDEX(Calendario!$A$4:$A$107,MATCH(A21,Calendario!$B$4:$B$107,1)),"")) | C21: =IF(A21="","",YEAR(A21)&"-"&TEXT(MONTH(A21),"00"))
B22: =IF(A22="","",IFERROR(INDEX(Calendario!$A$4:$A$107,MATCH(A22,Calendario!$B$4:$B$107,1)),"")) | C22: =IF(A22="","",YEAR(A22)&"-"&TEXT(MONTH(A22),"00"))
B23: =IF(A23="","",IFERROR(INDEX(Calendario!$A$4:$A$107,MATCH(A23,Calendario!$B$4:$B$107,1)),"")) | C23: =IF(A23="","",YEAR(A23)&"-"&TEXT(MONTH(A23),"00"))
B24: =IF(A24="","",IFERROR(INDEX(Calendario!$A$4:$A$107,MATCH(A24,Calendario!$B$4:$B$107,1)),"")) | C24: =IF(A24="","",YEAR(A24)&"-"&TEXT(MONTH(A24),"00"))
B25: =IF(A25="","",IFERROR(INDEX(Calendario!$A$4:$A$107,MATCH(A25,Calendario!$B$4:$B$107,1)),"")) | C25: =IF(A25="","",YEAR(A25)&"-"&TEXT(MONTH(A25),"00"))
B26: =IF(A26="","",IFERROR(INDEX(Calendario!$A$4:$A$107,MATCH(A26,Calendario!$B$4:$B$107,1)),"")) | C26: =IF(A26="","",YEAR(A26)&"-"&TEXT(MONTH(A26),"00"))
B27: =IF(A27="","",IFERROR(INDEX(Calendario!$A$4:$A$107,MATCH(A27,Calendario!$B$4:$B$107,1)),"")) | C27: =IF(A27="","",YEAR(A27)&"-"&TEXT(MONTH(A27),"00"))
B28: =IF(A28="","",IFERROR(INDEX(Calendario!$A$4:$A$107,MATCH(A28,Calendario!$B$4:$B$107,1)),"")) | C28: =IF(A28="","",YEAR(A28)&"-"&TEXT(MONTH(A28),"00"))
... B503: =IF(A503="","",IFERROR(INDEX(Calendario!$A$4:$A$107,MATCH(A503,Calendario!$B$4:$B$107,1)),"")) | C503: =IF(A503="","",YEAR(A503)&"-"&TEXT(MONTH(A503),"00"))

Sheet Leads_Canal
A1: Leads por canal de ingresso
A2: Uma linha por semana e canal. A soma deve bater com 'Leads recebidos' da Base_Semanal (há checagem no Resumo_Semanal).
A3: id_semana | B3: Canal | C3: Quantidade | D3: Observações
A4: 2026-S39 | B4: Instagram | C4: 16 | D4: Exemplo
A5: 2026-S39 | B5: Google | C5: 10 | D5: Exemplo
A6: 2026-S39 | B6: Indicação | C6: 7 | D6: Exemplo
A7: 2026-S39 | B7: WhatsApp direto | C7: 5 | D7: Exemplo
A8: 2026-S40 | B8: Instagram | C8: 20 | D8: Exemplo
A9: 2026-S40 | B9: Google | C9: 12 | D9: Exemplo
A10: 2026-S40 | B10: Indicação | C10: 8 | D10: Exemplo
A11: 2026-S40 | B11: WhatsApp direto | C11: 5 | D11: Exemplo

Sheet Reuniao_Semanal
A1: Registro qualitativo da reunião semanal
A2: Uma linha por semana. Os textos aparecem automaticamente no Painel_Semanal.
A3: id_semana | B3: Resultado geral (registrado) | C3: Pontos positivos | D3: Pontos a melhorar | E3: Pacientes críticos / risco de desistência | F3: Pontos pertinentes | G3: Problemas no atendimento | H3: Algo prejudicando a experiência? | I3: Descrição do que prejudica | J3: Demandas da recepção e equipe | K3: Pontos relevantes (próxima semana) | L3: Outros pontos | M3: Metas da semana | N3: Soluções para os problemas identificados
A4: 2026-S40 | B4: Melhor | C4: Receita acima da meta; 4 protocolos fechados por indicação | D4: Taxa de ocupação da tarde abaixo de 90%; 5 cancelamentos de atendimento | E4: Roberto A. — 2 faltas seguidas e parcela em atraso; Ana R. — reclamou de espera | F4: Pacientes elogiaram o novo protocolo de alongamento | G4: Espera de 15 min na recepção em dois dias (acúmulo às 8h) | H4: Sim | I4: Atraso na abertura da recepção às 7h50 | J4: Recepção pede roteiro de confirmação de consulta por WhatsApp | K4: Agenda da manhã já com 73% ocupada; reforçar captação para a tarde | L4: Manutenção do ar-condicionado da sala 2 agendada para quinta | M4: Receita R$ 32.000; 10 avaliações; ocupação total ≥ 85% | N4: Confirmação de consulta 24h antes por WhatsApp; escala da recepção a partir de 7h40
A5: 2026-S39 | B5: Igual | C5: Exemplo — substitua pelos dados reais

Sheet Plano_Acao
A1: Plano de ação 5W2H
A2: Uma linha por ação. As 8 primeiras ações de cada semana aparecem no Painel_Semanal.
A3: id_semana | B3: Ordem | C3: Problema / meta | D3: O quê (What) | E3: Por quê (Why) | F3: Onde (Where) | G3: Quando (When) | H3: Quem (Who) | I3: Como (How) | J3: Quanto (How much) | K3: Status | L3: chave
A4: 2026-S40 | B4: =IF(A4="","",COUNTIF($A$4:A4,A4)) -> 1 | C4: Espera na recepção às 8h | D4: Antecipar abertura da recepção | E4: Reduzir espera e reclamações | F4: Recepção | G4: 46301 | H4: Recepção | I4: Escala iniciando às 7h40; check-in antecipado | J4: 0 | K4: Em andamento | L4: =IF(A4="","",A4&"-"&B4) -> 2026-S40-1
A5: 2026-S40 | B5: =IF(A5="","",COUNTIF($A$4:A5,A5)) -> 2 | C5: Cancelamentos de atendimento | D5: Confirmar consultas 24h antes por WhatsApp | E5: Reduzir faltas e liberar horários | F5: Recepção | G5: 46304 | H5: Recepção | I5: Modelo de mensagem + lista diária de confirmação | J5: 0 | K5: A fazer | L5: =IF(A5="","",A5&"-"&B5) -> 2026-S40-2
A6: 2026-S40 | B6: =IF(A6="","",COUNTIF($A$4:A6,A6)) -> 3 | C6: Ocupação da tarde < 90% | D6: Campanha de captação para horários da tarde | E6: Elevar taxa de ocupação | F6: Marketing | G6: 46311 | H6: Ariosto | I6: Anúncio segmentado + oferta de avaliação à tarde | J6: 400 | K6: A fazer | L6: =IF(A6="","",A6&"-"&B6) -> 2026-S40-3
B7: =IF(A7="","",COUNTIF($A$4:A7,A7)) | L7: =IF(A7="","",A7&"-"&B7)
B8: =IF(A8="","",COUNTIF($A$4:A8,A8)) | L8: =IF(A8="","",A8&"-"&B8)
B9: =IF(A9="","",COUNTIF($A$4:A9,A9)) | L9: =IF(A9="","",A9&"-"&B9)
B10: =IF(A10="","",COUNTIF($A$4:A10,A10)) | L10: =IF(A10="","",A10&"-"&B10)
B11: =IF(A11="","",COUNTIF($A$4:A11,A11)) | L11: =IF(A11="","",A11&"-"&B11)
B12: =IF(A12="","",COUNTIF($A$4:A12,A12)) | L12: =IF(A12="","",A12&"-"&B12)
B13: =IF(A13="","",COUNTIF($A$4:A13,A13)) | L13: =IF(A13="","",A13&"-"&B13)
B14: =IF(A14="","",COUNTIF($A$4:A14,A14)) | L14: =IF(A14="","",A14&"-"&B14)
B15: =IF(A15="","",COUNTIF($A$4:A15,A15)) | L15: =IF(A15="","",A15&"-"&B15)
B16: =IF(A16="","",COUNTIF($A$4:A16,A16)) | L16: =IF(A16="","",A16&"-"&B16)
B17: =IF(A17="","",COUNTIF($A$4:A17,A17)) | L17: =IF(A17="","",A17&"-"&B17)
B18: =IF(A18="","",COUNTIF($A$4:A18,A18)) | L18: =IF(A18="","",A18&"-"&B18)
... B503: =IF(A503="","",COUNTIF($A$4:A503,A503)) | L503: =IF(A503="","",A503&"-"&B503)

Sheet Resumo_Semanal
A1: Resumo semanal (calculado)
A2: Não edite: tudo é calculado a partir das abas de coleta. Base do Painel_Semanal.
A3: id_semana | B3: Início | C3: Fim | D3: Mês | E3: Leads recebidos | F3: Aval. agendadas | G3: Aval. canceladas | H3: Aval. realizadas F1 | I3: Aval. realizadas F2 | J3: Aval. realizadas total | K3: Taxa canc. avaliações | L3: Contratos F1 | M3: Contratos F2 | N3: Contratos total | O3: Conversão aval→contrato | P3: Atend. F1 | Q3: Atend. F2 | R3: Atend. total | S3: Cancelamentos atend. | T3: Novos pacientes | U3: Ocupação manhã | V3: Ocupação tarde | W3: Ocupação total | X3: Tempo médio F1 | Y3: Desvio F1 | Z3: Tempo médio F2 | AA3: Desvio F2 | AB3: Aval. contratadas (qtd) | AC3: Valor avaliações | AD3: Protocolos contratados (qtd) | AE3: Valor protocolos | AF3: Valor total contratado | AG3: Contratos à vista (qtd) | AH3: Contratos parcelados (qtd) | AI3: Receitas | AJ3: Gastos | AK3: Impostos | AL3: Marketing | AM3: Resultado | AN3: Receita vs meta | AO3: Gastos vs meta | AP3: CAC (marketing / novos pac.) | AQ3: Receita acum. mês | AR3: Gastos acum. mês | AS3: Leads por canal (soma) | AT3: Checagem leads | AU3: Checagem contratos
A4: =Base_Semanal!A4 -> 2026-S02 | B4: =Base_Semanal!B4 -> 46027 | C4: =Base_Semanal!C4 -> 46033 | D4: =Base_Semanal!D4 -> 2026-01 | E4: =Base_Semanal!E4 -> 0 | F4: =Base_Semanal!F4 -> 0 | G4: =Base_Semanal!G4 -> 0 | H4: =Base_Semanal!H4 -> 0 | I4: =Base_Semanal!I4 -> 0 | J4: =H4+I4 -> 0 | K4: =IF(F4=0,"",G4/F4) | L4: =Base_Semanal!J4 -> 0 | M4: =Base_Semanal!K4 -> 0 | N4: =L4+M4 -> 0 | O4: =IF(J4=0,"",N4/J4) | P4: =Base_Semanal!L4 -> 0 | Q4: =Base_Semanal!M4 -> 0 | R4: =P4+Q4 -> 0 | S4: =Base_Semanal!N4 -> 0 | T4: =Base_Semanal!O4 -> 0 | U4: =IF(Base_Semanal!P4=0,"",Base_Semanal!Q4/Base_Semanal!P4) | V4: =IF(Base_Semanal!R4=0,"",Base_Semanal!S4/Base_Semanal!R4) | W4: =IF(Base_Semanal!P4+Base_Semanal!R4=0,"",(Base_Semanal!Q4+Base_Semanal!S4)/(Base_Semanal!P4+Base_Semanal!R4)) | X4: =Base_Semanal!T4 -> 0 | Y4: =Base_Semanal!U4 -> 0 | Z4: =Base_Semanal!V4 -> 0 | AA4: =Base_Semanal!W4 -> 0 | AB4: =COUNTIFS(Contratos!$B$4:$B$503,$A4,Contratos!$E$4:$E$503,"Avaliação") -> 0 | AC4: =SUMIFS(Contratos!$I$4:$I$503,Contratos!$B$4:$B$503,$A4,Contratos!$E$4:$E$503,"Avaliação") -> 0 | AD4: =COUNTIFS(Contratos!$B$4:$B$503,$A4,Contratos!$E$4:$E$503,"Protocolo") -> 0 | AE4: =SUMIFS(Contratos!$I$4:$I$503,Contratos!$B$4:$B$503,$A4,Contratos!$E$4:$E$503,"Protocolo") -> 0 | AF4: =AC4+AE4 -> 0 | AG4: =COUNTIFS(Contratos!$B$4:$B$503,$A4,Contratos!$J$4:$J$503,"À vista") -> 0 | AH4: =COUNTIFS(Contratos!$B$4:$B$503,$A4,Contratos!$J$4:$J$503,"Parcelado") -> 0 | AI4: =SUMIFS(Financeiro!$G$4:$G$503,Financeiro!$B$4:$B$503,$A4,Financeiro!$D$4:$D$503,"Receita",Financeiro!$H$4:$H$503,"<>Cancelado") -> 0 | AJ4: =SUMIFS(Financeiro!$G$4:$G$503,Financeiro!$B$4:$B$503,$A4,Financeiro!$D$4:$D$503,"Gasto",Financeiro!$H$4:$H$503,"<>Cancelado") -> 0 | AK4: =SUMIFS(Financeiro!$G$4:$G$503,Financeiro!$B$4:$B$503,$A4,Financeiro!$D$4:$D$503,"Imposto",Financeiro!$H$4:$H$503,"<>Cancelado") -> 0 | AL4: =SUMIFS(Financeiro!$G$4:$G$503,Financeiro!$B$4:$B$503,$A4,Financeiro!$D$4:$D$503,"Marketing",Financeiro!$H$4:$H$503,"<>Cancelado") -> 0 | AM4: =AI4-AJ4-AK4-AL4 -> 0 | AN4: =IF(Config!$B$16=0,"",AI4/Config!$B$16) -> 0 | AO4: =IF(Config!$B$17=0,"",AJ4/Config!$B$17) -> 0 | AP4: =IF(T4=0,"",AL4/T4) | AQ4: =SUMIFS($AI$4:$AI$107,$D$4:$D$107,$D4,$B$4:$B$107,"<="&$B4) -> 0 | AR4: =SUMIFS($AJ$4:$AJ$107,$D$4:$D$107,$D4,$B$4:$B$107,"<="&$B4) -> 0 | AS4: =SUMIFS(Leads_Canal!$C$4:$C$503,Leads_Canal!$A$4:$A$503,$A4) -> 0 | AT4: =IF(E4=0,"",IF(E4=AR4,"OK","Divergente")) | AU4: =IF(N4=0,"",IF(N4=AD4,"OK","Divergente"))
A5: =Base_Semanal!A5 -> 2026-S03 | B5: =Base_Semanal!B5 -> 46034 | C5: =Base_Semanal!C5 -> 46040 | D5: =Base_Semanal!D5 -> 2026-01 | E5: =Base_Semanal!E5 -> 0 | F5: =Base_Semanal!F5 -> 0 | G5: =Base_Semanal!G5 -> 0 | H5: =Base_Semanal!H5 -> 0 | I5: =Base_Semanal!I5 -> 0 | J5: =H5+I5 -> 0 | K5: =IF(F5=0,"",G5/F5) | L5: =Base_Semanal!J5 -> 0 | M5: =Base_Semanal!K5 -> 0 | N5: =L5+M5 -> 0 | O5: =IF(J5=0,"",N5/J5) | P5: =Base_Semanal!L5 -> 0 | Q5: =Base_Semanal!M5 -> 0 | R5: =P5+Q5 -> 0 | S5: =Base_Semanal!N5 -> 0 | T5: =Base_Semanal!O5 -> 0 | U5: =IF(Base_Semanal!P5=0,"",Base_Semanal!Q5/Base_Semanal!P5) | V5: =IF(Base_Semanal!R5=0,"",Base_Semanal!S5/Base_Semanal!R5) | W5: =IF(Base_Semanal!P5+Base_Semanal!R5=0,"",(Base_Semanal!Q5+Base_Semanal!S5)/(Base_Semanal!P5+Base_Semanal!R5)) | X5: =Base_Semanal!T5 -> 0 | Y5: =Base_Semanal!U5 -> 0 | Z5: =Base_Semanal!V5 -> 0 | AA5: =Base_Semanal!W5 -> 0 | AB5: =COUNTIFS(Contratos!$B$4:$B$503,$A5,Contratos!$E$4:$E$503,"Avaliação") -> 0 | AC5: =SUMIFS(Contratos!$I$4:$I$503,Contratos!$B$4:$B$503,$A5,Contratos!$E$4:$E$503,"Avaliação") -> 0 | AD5: =COUNTIFS(Contratos!$B$4:$B$503,$A5,Contratos!$E$4:$E$503,"Protocolo") -> 0 | AE5: =SUMIFS(Contratos!$I$4:$I$503,Contratos!$B$4:$B$503,$A5,Contratos!$E$4:$E$503,"Protocolo") -> 0 | AF5: =AC5+AE5 -> 0 | AG5: =COUNTIFS(Contratos!$B$4:$B$503,$A5,Contratos!$J$4:$J$503,"À vista") -> 0 | AH5: =COUNTIFS(Contratos!$B$4:$B$503,$A5,Contratos!$J$4:$J$503,"Parcelado") -> 0 | AI5: =SUMIFS(Financeiro!$G$4:$G$503,Financeiro!$B$4:$B$503,$A5,Financeiro!$D$4:$D$503,"Receita",Financeiro!$H$4:$H$503,"<>Cancelado") -> 0 | AJ5: =SUMIFS(Financeiro!$G$4:$G$503,Financeiro!$B$4:$B$503,$A5,Financeiro!$D$4:$D$503,"Gasto",Financeiro!$H$4:$H$503,"<>Cancelado") -> 0 | AK5: =SUMIFS(Financeiro!$G$4:$G$503,Financeiro!$B$4:$B$503,$A5,Financeiro!$D$4:$D$503,"Imposto",Financeiro!$H$4:$H$503,"<>Cancelado") -> 0 | AL5: =SUMIFS(Financeiro!$G$4:$G$503,Financeiro!$B$4:$B$503,$A5,Financeiro!$D$4:$D$503,"Marketing",Financeiro!$H$4:$H$503,"<>Cancelado") -> 0 | AM5: =AI5-AJ5-AK5-AL5 -> 0 | AN5: =IF(Config!$B$16=0,"",AI5/Config!$B$16) -> 0 | AO5: =IF(Config!$B$17=0,"",AJ5/Config!$B$17) -> 0 | AP5: =IF(T5=0,"",AL5/T5) | AQ5: =SUMIFS($AI$4:$AI$107,$D$4:$D$107,$D5,$B$4:$B$107,"<="&$B5) -> 0 | AR5: =SUMIFS($AJ$4:$AJ$107,$D$4:$D$107,$D5,$B$4:$B$107,"<="&$B5) -> 0 | AS5: =SUMIFS(Leads_Canal!$C$4:$C$503,Leads_Canal!$A$4:$A$503,$A5) -> 0 | AT5: =IF(E5=0,"",IF(E5=AR5,"OK","Divergente")) | AU5: =IF(N5=0,"",IF(N5=AD5,"OK","Divergente"))
A6: =Base_Semanal!A6 -> 2026-S04 | B6: =Base_Semanal!B6 -> 46041 | C6: =Base_Semanal!C6 -> 46047 | D6: =Base_Semanal!D6 -> 2026-01 | E6: =Base_Semanal!E6 -> 0 | F6: =Base_Semanal!F6 -> 0 | G6: =Base_Semanal!G6 -> 0 | H6: =Base_Semanal!H6 -> 0 | I6: =Base_Semanal!I6 -> 0 | J6: =H6+I6 -> 0 | K6: =IF(F6=0,"",G6/F6) | L6: =Base_Semanal!J6 -> 0 | M6: =Base_Semanal!K6 -> 0 | N6: =L6+M6 -> 0 | O6: =IF(J6=0,"",N6/J6) | P6: =Base_Semanal!L6 -> 0 | Q6: =Base_Semanal!M6 -> 0 | R6: =P6+Q6 -> 0 | S6: =Base_Semanal!N6 -> 0 | T6: =Base_Semanal!O6 -> 0 | U6: =IF(Base_Semanal!P6=0,"",Base_Semanal!Q6/Base_Semanal!P6) | V6: =IF(Base_Semanal!R6=0,"",Base_Semanal!S6/Base_Semanal!R6) | W6: =IF(Base_Semanal!P6+Base_Semanal!R6=0,"",(Base_Semanal!Q6+Base_Semanal!S6)/(Base_Semanal!P6+Base_Semanal!R6)) | X6: =Base_Semanal!T6 -> 0 | Y6: =Base_Semanal!U6 -> 0 | Z6: =Base_Semanal!V6 -> 0 | AA6: =Base_Semanal!W6 -> 0 | AB6: =COUNTIFS(Contratos!$B$4:$B$503,$A6,Contratos!$E$4:$E$503,"Avaliação") -> 0 | AC6: =SUMIFS(Contratos!$I$4:$I$503,Contratos!$B$4:$B$503,$A6,Contratos!$E$4:$E$503,"Avaliação") -> 0 | AD6: =COUNTIFS(Contratos!$B$4:$B$503,$A6,Contratos!$E$4:$E$503,"Protocolo") -> 0 | AE6: =SUMIFS(Contratos!$I$4:$I$503,Contratos!$B$4:$B$503,$A6,Contratos!$E$4:$E$503,"Protocolo") -> 0 | AF6: =AC6+AE6 -> 0 | AG6: =COUNTIFS(Contratos!$B$4:$B$503,$A6,Contratos!$J$4:$J$503,"À vista") -> 0 | AH6: =COUNTIFS(Contratos!$B$4:$B$503,$A6,Contratos!$J$4:$J$503,"Parcelado") -> 0 | AI6: =SUMIFS(Financeiro!$G$4:$G$503,Financeiro!$B$4:$B$503,$A6,Financeiro!$D$4:$D$503,"Receita",Financeiro!$H$4:$H$503,"<>Cancelado") -> 0 | AJ6: =SUMIFS(Financeiro!$G$4:$G$503,Financeiro!$B$4:$B$503,$A6,Financeiro!$D$4:$D$503,"Gasto",Financeiro!$H$4:$H$503,"<>Cancelado") -> 0 | AK6: =SUMIFS(Financeiro!$G$4:$G$503,Financeiro!$B$4:$B$503,$A6,Financeiro!$D$4:$D$503,"Imposto",Financeiro!$H$4:$H$503,"<>Cancelado") -> 0 | AL6: =SUMIFS(Financeiro!$G$4:$G$503,Financeiro!$B$4:$B$503,$A6,Financeiro!$D$4:$D$503,"Marketing",Financeiro!$H$4:$H$503,"<>Cancelado") -> 0 | AM6: =AI6-AJ6-AK6-AL6 -> 0 | AN6: =IF(Config!$B$16=0,"",AI6/Config!$B$16) -> 0 | AO6: =IF(Config!$B$17=0,"",AJ6/Config!$B$17) -> 0 | AP6: =IF(T6=0,"",AL6/T6) | AQ6: =SUMIFS($AI$4:$AI$107,$D$4:$D$107,$D6,$B$4:$B$107,"<="&$B6) -> 0 | AR6: =SUMIFS($AJ$4:$AJ$107,$D$4:$D$107,$D6,$B$4:$B$107,"<="&$B6) -> 0 | AS6: =SUMIFS(Leads_Canal!$C$4:$C$503,Leads_Canal!$A$4:$A$503,$A6) -> 0 | AT6: =IF(E6=0,"",IF(E6=AR6,"OK","Divergente")) | AU6: =IF(N6=0,"",IF(N6=AD6,"OK","Divergente"))
A7: =Base_Semanal!A7 -> 2026-S05 | B7: =Base_Semanal!B7 -> 46048 | C7: =Base_Semanal!C7 -> 46054 | D7: =Base_Semanal!D7 -> 2026-01 | E7: =Base_Semanal!E7 -> 0 | F7: =Base_Semanal!F7 -> 0 | G7: =Base_Semanal!G7 -> 0 | H7: =Base_Semanal!H7 -> 0 | I7: =Base_Semanal!I7 -> 0 | J7: =H7+I7 -> 0 | K7: =IF(F7=0,"",G7/F7) | L7: =Base_Semanal!J7 -> 0 | M7: =Base_Semanal!K7 -> 0 | N7: =L7+M7 -> 0 | O7: =IF(J7=0,"",N7/J7) | P7: =Base_Semanal!L7 -> 0 | Q7: =Base_Semanal!M7 -> 0 | R7: =P7+Q7 -> 0 | S7: =Base_Semanal!N7 -> 0 | T7: =Base_Semanal!O7 -> 0 | U7: =IF(Base_Semanal!P7=0,"",Base_Semanal!Q7/Base_Semanal!P7) | V7: =IF(Base_Semanal!R7=0,"",Base_Semanal!S7/Base_Semanal!R7) | W7: =IF(Base_Semanal!P7+Base_Semanal!R7=0,"",(Base_Semanal!Q7+Base_Semanal!S7)/(Base_Semanal!P7+Base_Semanal!R7)) | X7: =Base_Semanal!T7 -> 0 | Y7: =Base_Semanal!U7 -> 0 | Z7: =Base_Semanal!V7 -> 0 | AA7: =Base_Semanal!W7 -> 0 | AB7: =COUNTIFS(Contratos!$B$4:$B$503,$A7,Contratos!$E$4:$E$503,"Avaliação") -> 0 | AC7: =SUMIFS(Contratos!$I$4:$I$503,Contratos!$B$4:$B$503,$A7,Contratos!$E$4:$E$503,"Avaliação") -> 0 | AD7: =COUNTIFS(Contratos!$B$4:$B$503,$A7,Contratos!$E$4:$E$503,"Protocolo") -> 0 | AE7: =SUMIFS(Contratos!$I$4:$I$503,Contratos!$B$4:$B$503,$A7,Contratos!$E$4:$E$503,"Protocolo") -> 0 | AF7: =AC7+AE7 -> 0 | AG7: =COUNTIFS(Contratos!$B$4:$B$503,$A7,Contratos!$J$4:$J$503,"À vista") -> 0 | AH7: =COUNTIFS(Contratos!$B$4:$B$503,$A7,Contratos!$J$4:$J$503,"Parcelado") -> 0 | AI7: =SUMIFS(Financeiro!$G$4:$G$503,Financeiro!$B$4:$B$503,$A7,Financeiro!$D$4:$D$503,"Receita",Financeiro!$H$4:$H$503,"<>Cancelado") -> 0 | AJ7: =SUMIFS(Financeiro!$G$4:$G$503,Financeiro!$B$4:$B$503,$A7,Financeiro!$D$4:$D$503,"Gasto",Financeiro!$H$4:$H$503,"<>Cancelado") -> 0 | AK7: =SUMIFS(Financeiro!$G$4:$G$503,Financeiro!$B$4:$B$503,$A7,Financeiro!$D$4:$D$503,"Imposto",Financeiro!$H$4:$H$503,"<>Cancelado") -> 0 | AL7: =SUMIFS(Financeiro!$G$4:$G$503,Financeiro!$B$4:$B$503,$A7,Financeiro!$D$4:$D$503,"Marketing",Financeiro!$H$4:$H$503,"<>Cancelado") -> 0 | AM7: =AI7-AJ7-AK7-AL7 -> 0 | AN7: =IF(Config!$B$16=0,"",AI7/Config!$B$16) -> 0 | AO7: =IF(Config!$B$17=0,"",AJ7/Config!$B$17) -> 0 | AP7: =IF(T7=0,"",AL7/T7) | AQ7: =SUMIFS($AI$4:$AI$107,$D$4:$D$107,$D7,$B$4:$B$107,"<="&$B7) -> 0 | AR7: =SUMIFS($AJ$4:$AJ$107,$D$4:$D$107,$D7,$B$4:$B$107,"<="&$B7) -> 0 | AS7: =SUMIFS(Leads_Canal!$C$4:$C$503,Leads_Canal!$A$4:$A$503,$A7) -> 0 | AT7: =IF(E7=0,"",IF(E7=AR7,"OK","Divergente")) | AU7: =IF(N7=0,"",IF(N7=AD7,"OK","Divergente"))
